<?xml version='1.0'?>
<sdf version='1.4'>
  <model name="test_bot">
        <static>false</static> <!--Make this false to make the bot move-->

          <link name='chassis'>
            <pose>0 0 0.12 0 0 0</pose>

            <collision name='collision'>
              <geometry>
                <box>
                  <size>.18 .18 .17</size>
                </box>
              </geometry>
            </collision>

            <visual name='visual'>
              <geometry>
                <box>
                  <size>.18 .18 .17</size>
                </box>
              </geometry>
            </visual>

 <collision name='caster_collision'>
            <pose>-0.068 0 -0.085 0 0 0</pose>
            <geometry>
                <sphere>
                <radius>.027</radius>
              </sphere>
            </geometry>

            <surface>
              <friction>
                <ode>
                  <mu>0</mu>
                  <mu2>0</mu2>
                  <slip1>1.0</slip1>
                  <slip2>1.0</slip2>
                </ode>
              </friction>
            </surface>
          </collision>

          <visual name='caster_visual'>
            <pose>-0.068 0 -0.085 0 0 0</pose>
            <geometry>
              <sphere>
                <radius>.027</radius>
              </sphere>
            </geometry>
          </visual>
     </link>



<link name="left_wheel">
        <pose>0.065 0.103 0.08 0 1.5707 1.5707</pose>
        <collision name="collision">
          <geometry>
            <cylinder>
              <radius>.07</radius>
              <length>.025</length>
            </cylinder>
          </geometry>
        </collision>
        <visual name="visual">
          <geometry>
            <cylinder>
              <radius>.07</radius>
              <length>.025</length>
            </cylinder>
          </geometry>
        </visual>
      </link>


 <link name="right_wheel">
        <pose>0.065 -0.103 0.08 0 1.5707 1.5707</pose>
        <collision name="collision">
          <geometry>
            <cylinder>
              <radius>.07</radius>
              <length>.025</length>
            </cylinder>
          </geometry>
        </collision>
        <visual name="visual">
          <geometry>
            <cylinder>
              <radius>.07</radius>
              <length>.025</length>
            </cylinder>
          </geometry>
        </visual>
      </link>


<joint type="revolute" name="left_wheel_hinge">
        <pose>0 0 -0.08 0 0 0</pose>
        <child>left_wheel</child>
        <parent>chassis</parent>
        <axis>
          <xyz>0 1 0</xyz>
        </axis>
      </joint>

      <joint type="revolute" name="right_wheel_hinge">
        <pose>0 0 0.08 0 0 0</pose>
        <child>right_wheel</child>
        <parent>chassis</parent>
        <axis>
          <xyz>0 1 0</xyz>
        </axis>
      </joint>




<!--Differential drive plugin-->
 <plugin name="differential_drive_controller" filename="libgazebo_ros_diff_drive.so">
      <legacyMode>false</legacyMode>
      <alwaysOn>true</alwaysOn>
      <updateRate>20</updateRate>
      <leftJoint>left_wheel_hinge</leftJoint>
      <rightJoint>left_wheel_hinge</rightJoint>
      <wheelSeparation>0.206</wheelSeparation>
      <wheelDiameter>0.14</wheelDiameter>
      <torque>20</torque>
      <commandTopic>cmd_vel</commandTopic>
      <odometryTopic>odom</odometryTopic>
      <odometryFrame>odom</odometryFrame>
      <robotBaseFrame>chassis</robotBaseFrame>
    </plugin>



<!--definfing hokuyo-->

<model name='hokuyo'>
      <link name='link'>
        <gravity>0</gravity>
        <inertial>
          <mass>0.1</mass>
        </inertial>
        <visual name='visual'>
          <geometry>
            <mesh>
              <uri>model://hokuyo/meshes/hokuyo.dae</uri>
            </mesh>
          </geometry>
        </visual>
        <sensor name='laser' type='ray'>
          <pose frame=''>0.01 0 0.03 0 0 3.14</pose>
          <ray>
            <scan>
              <horizontal>
                <samples>8</samples>
                <resolution>1</resolution>
                <min_angle>-1.0</min_angle>
                <max_angle>1.0</max_angle>
              </horizontal>
            </scan>
            <range>
              <min>0.02</min>
              <max>1</max>
              <resolution>0.01</resolution>
            </range>
            <noise>
          <type>gaussian</type>
          <mean>0.0</mean>
          <stddev>0.01</stddev>
        	</noise>
          </ray>


          <!-- <plugin name='laser' filename='libRayPlugin.so'/> -->
           <plugin name="gazebo_ros_head_hokuyo_controller" filename="libgazebo_ros_laser.so">
          <topicName>/mybot/laser/scan</topicName>
          <frameName>odom</frameName>
        </plugin>
          <always_on>1</always_on>
          <update_rate>30</update_rate>
          <visualize>1</visualize>
        </sensor>
      </link>
      <pose frame=''>-0.06 0 0.18 0 0 0</pose>
    </model>


 <joint name='hokuyo_joint' type='fixed'>
      <parent>chassis</parent>
      <child>hokuyo::link</child>
      <pose frame=''>-0.06 0 0.18 0 0 0</pose>
      <physics>
        <ode>
          <limit>
            <cfm>0</cfm>
            <erp>0.2</erp>
          </limit>
          <suspension>
            <cfm>0</cfm>
            <erp>0.2</erp>
          </suspension>
        </ode>
      </physics>
    </joint>
    <static>0</static>
    <allow_auto_disable>1</allow_auto_disable>




  </model>
</sdf>
